Workbook

Sheet Gelen İşçiler
A1: Gelen İşçiler
A2: Oprt1
A3: Oprt3
A4: Oprt4
A5: Oprt5
A6: Oprt6
A7: Oprt7
A8: Oprt8
A9: Oprt9
A10: Oprt10
A11: Oprt11
A12: Oprt12
... A94: Oprt95

Sheet İstasyonlar
A1: İstasyon adres | B1: Operasyon No | C1: Süre (sn) | D1: ceza | E1: Sıra | F1: SABİT İSTASYONLAR
A2: OP_A020040 | B2: OP_A020040_6 | C2: 2.8 | D2: =IF(F2="Sabit",999999999,10000) -> 999999999 | E2: 2 | F2: Sabit
A3: OP_A020040 | B3: OP_A020040_7 | C3: 2.8 | D3: =IF(F3="Sabit",999999999,10000) -> 999999999 | E3: 2 | F3: Sabit
A4: OP_A020040 | B4: OP_A020040_2 | C4: 3.5 | D4: =IF(F4="Sabit",999999999,10000) -> 999999999 | E4: 2 | F4: Sabit
A5: OP_A020040 | B5: OP_A020040_4 | C5: 3.5 | D5: =IF(F5="Sabit",999999999,10000) -> 999999999 | E5: 2 | F5: Sabit
A6: OP_A020040 | B6: OP_A020040_5 | C6: 4.5 | D6: =IF(F6="Sabit",999999999,10000) -> 999999999 | E6: 2 | F6: Sabit
A7: OP_A020040 | B7: OP_A020040_1 | C7: 9.5 | D7: =IF(F7="Sabit",999999999,10000) -> 999999999 | E7: 2 | F7: Sabit
A8: OP_A020040 | B8: OP_A020040_3 | C8: 9.5 | D8: =IF(F8="Sabit",999999999,10000) -> 999999999 | E8: 2 | F8: Sabit
A9: OP_A020060 | B9: OP_A020060_1 | C9: 6.1 | D9: =IF(F9="Sabit",999999999,1000000) -> 1000000 | E9: 3
A10: OP_A020060 | B10: OP_A020060_2 | C10: 6.1 | D10: =IF(F10="Sabit",999999999,1000000) -> 1000000 | E10: 3
A11: OP_A020080 | B11: OP_A020080_1 | C11: 5.8 | D11: =IF(F11="Sabit",999999999,1000000) -> 999999999 | E11: 4 | F11: Sabit
A12: OP_A020080 | B12: OP_A020080_2 | C12: 6.4 | D12: =IF(F12="Sabit",999999999,1000000) -> 999999999 | E12: 4 | F12: Sabit
A13: OP_A020080_A | B13: OP_A020080_A_3 | C13: 1 | D13: =IF(F13="Sabit",999999999,1000000) -> 999999999 | E13: 5 | F13: Sabit
A14: OP_A020080_A | B14: OP_A020080_A_3 | C14: 1 | D14: =IF(F14="Sabit",999999999,1000000) -> 999999999 | E14: 5 | F14: Sabit
A15: OP_A020080_A | B15: OP_A020080_A_4 | C15: 2.8 | D15: =IF(F15="Sabit",999999999,1000000) -> 999999999 | E15: 5 | F15: Sabit
A16: OP_A020080_A | B16: OP_A020080_A_1 | C16: 6.1 | D16: =IF(F16="Sabit",999999999,1000000) -> 999999999 | E16: 5 | F16: Sabit
A17: OP_A020080_A | B17: OP_A020080_A_1 | C17: 6.1 | D17: =IF(F17="Sabit",999999999,1000000) -> 999999999 | E17: 5 | F17: Sabit
A18: OP_A020080_A | B18: OP_A020080_A_2 | C18: 6.4 | D18: =IF(F18="Sabit",999999999,1000000) -> 999999999 | E18: 5 | F18: Sabit
A19: OP_A020080_A | B19: OP_A020080_A_2 | C19: 6.4 | D19: =IF(F19="Sabit",999999999,1000000) -> 999999999 | E19: 5 | F19: Sabit
A20: OP_A020140 | B20: OP_A020140_2 | C20: 3.1 | D20: =IF(F20="Sabit",999999999,1000000) -> 1000000 | E20: 6
A21: OP_A020140 | B21: OP_A020140_1 | C21: 9.5 | D21: =IF(F21="Sabit",999999999,1000000) -> 1000000 | E21: 6
A22: OP_A020160 | B22: OP_A020160_3 | C22: 0.3 | D22: =IF(F22="Sabit",999999999,1000000) -> 1000000 | E22: 7
A23: OP_A020160 | B23: OP_A020160_3 | C23: 0.3 | D23: =IF(F23="Sabit",999999999,1000000) -> 1000000 | E23: 7
A24: OP_A020160 | B24: OP_A020160_3 | C24: 0.3 | D24: =IF(F24="Sabit",999999999,1000000) -> 1000000 | E24: 7
A25: OP_A020160 | B25: OP_A020160_3 | C25: 0.3 | D25: =IF(F25="Sabit",999999999,1000000) -> 1000000 | E25: 7
A26: OP_A020160 | B26: OP_A020160_2 | C26: 3.1 | D26: =IF(F26="Sabit",999999999,1000000) -> 1000000 | E26: 7
A27: OP_A020160 | B27: OP_A020160_2 | C27: 3.1 | D27: =IF(F27="Sabit",999999999,1000000) -> 1000000 | E27: 7
A28: OP_A020160 | B28: OP_A020160_2 | C28: 3.1 | D28: =IF(F28="Sabit",999999999,1000000) -> 1000000 | E28: 7
A29: OP_A020160 | B29: OP_A020160_2 | C29: 3.1 | D29: =IF(F29="Sabit",999999999,1000000) -> 1000000 | E29: 7
A30: OP_A020160 | B30: OP_A020160_2 | C30: 3.1 | D30: =IF(F30="Sabit",999999999,1000000) -> 1000000 | E30: 7
A31: OP_A020160 | B31: OP_A020160_4 | C31: 4.1 | D31: =IF(F31="Sabit",999999999,1000000) -> 1000000 | E31: 7
... A51: OP_A020220 | B51: OP_A020220_1 | C51: 6.5 | D51: =IF(F51="Sabit",999999999,1000000) -> 1000000 | E51: 10
A52: OP_A020300 | B52: OP_A020300_3 | C52: 2.4 | D52: =IF(F52="Sabit",999999999,1000000) -> 999999999 | E52: 11 | F52: Sabit
A53: OP_A020300 | B53: OP_A020300_4 | C53: 2.7 | D53: =IF(F53="Sabit",999999999,1000000) -> 999999999 | E53: 11 | F53: Sabit
A54: OP_A020300 | B54: OP_A020300_1 | C54: 5.3 | D54: =IF(F54="Sabit",999999999,1000000) -> 999999999 | E54: 11 | F54: Sabit
A55: OP_A020300 | B55: OP_A020300_2 | C55: 6.4 | D55: =IF(F55="Sabit",999999999,1000000) -> 999999999 | E55: 11 | F55: Sabit
A56: OP_A020330 | B56: OP_A020330_1 | C56: 9.2 | D56: =IF(F56="Sabit",999999999,1000000) -> 999999999 | E56: 12 | F56: Sabit
A57: OP_A020330 | B57: OP_A020330_2 | C57: 9.2 | D57: =IF(F57="Sabit",999999999,1000000) -> 999999999 | E57: 12 | F57: Sabit
A58: OP_A020330 | B58: OP_A020330_3 | C58: 9.2 | D58: =IF(F58="Sabit",999999999,1000000) -> 999999999 | E58: 12 | F58: Sabit
A59: OP_A020330 | B59: OP_A020330_4 | C59: 9.2 | D59: =IF(F59="Sabit",999999999,1000000) -> 999999999 | E59: 12 | F59: Sabit
...

Sheet Performans Çarpanları
A1: Operatör | B1: Çarpan | C1: Katsayı
A2: Oprt1 | B2: 0.94360068 | C2: 1
A3: Oprt2 | B3: 0.99068784 | C3: 1
A4: Oprt3 | B4: 0.8763614 | C4: 1
A5: Oprt4 | B5: 0.96990389 | C5: 1
A6: Oprt5 | B6: 0.89127324 | C6: 1
A7: Oprt6 | B7: 0.89617986 | C7: 1
A8: Oprt7 | B8: 0.88929077 | C8: 1
A9: Oprt8 | B9: 0.9825465 | C9: 1
A10: Oprt9 | B10: 0.98874243 | C10: 1
A11: Oprt10 | B11: 0.97535103 | C11: 1
A12: Oprt11 | B12: 1.0230998 | C12: 1
A13: Oprt12 | B13: 0.96664438 | C13: 1
... A89: Oprt88 | B89: 0.94366622 | C89: 1
A90: Oprt89 | B90: 0.93549583
A91: Oprt90 | B91: 0.9365617
A92: Oprt91 | B92: 0.90711005
A93: Oprt92 | B93: 1.0556101
A94: Oprt93 | B94: 0.95482112
A95: Oprt94 | B95: 0.89695838
A96: Oprt95 | B96: 1

Sheet Master Yetenekleri
A1: Operasyonlar | B1: Master Worker
A2: OP_A020060_1 | B2: Oprt26
A3: OP_A020060_2 | B3: Oprt26
A4: OP_A020080_1 | B4: Oprt26
A5: OP_A020080_2 | B5: Oprt26
A6: OP_A020080_A_2 | B6: Oprt26
A7: OP_A020080_A_3 | B7: Oprt26
A8: OP_A020140_1 | B8: Oprt26
A9: OP_A020140_2 | B9: Oprt26
A10: OP_A020160_1 | B10: Oprt26
A11: OP_A020160_2 | B11: Oprt26
A12: OP_A020160_3 | B12: Oprt26
... A278: OP_FG2_1 | B278: Oprt58

Sheet 97653 için istasyonlar
A1: İstasyon adres | B1: Operasyon No | C1: İstasyon Bilgisi Operatör 1 | D1: İstasyon Bilgisi Operatör 2 | E1: İstasyon Bilgisi Operatör 3 | F1: İstasyon Bilgisi Operatör 4 | G1: İstasyon Bilgisi Operatör 5 | H1: SÜRE (SN) | I1: Ceza | J1: Sıra
A2: OP_A020080 | B2: OP_A020080_1 | C2: Oprt3 | D2: Oprt4 | E2: Oprt15 | H2: 5.8 | I2: =VLOOKUP(A2,İstasyonlar!$A$2:$D$776,4,0) -> 999999999 | J2: 1 | K2: =IF(I2=1000000,"","Sabit") -> Sabit
A3: OP_A020080 | B3: OP_A020080_2 | C3: Oprt3 | D3: Oprt4 | E3: Oprt15 | H3: 6.4 | I3: =VLOOKUP(A3,İstasyonlar!$A$2:$D$776,4,0) -> 999999999 | J3: =IF(A3=A2, J2, J2+1) -> 1 | K3: =IF(I3=1000000,"","Sabit") -> Sabit
A4: OP_A020080_A | B4: OP_A020080_A_1 | C4: Oprt4 | D4: Oprt3 | H4: 6.1 | I4: =VLOOKUP(A4,İstasyonlar!$A$2:$D$776,4,0) -> 999999999 | J4: =IF(A4=A3, J3, J3+1) -> 2 | K4: =IF(I4=1000000,"","Sabit") -> Sabit
A5: OP_A020080_A | B5: OP_A020080_A_2 | C5: Oprt4 | D5: Oprt3 | H5: 6.4 | I5: =VLOOKUP(A5,İstasyonlar!$A$2:$D$776,4,0) -> 999999999 | J5: =IF(A5=A4, J4, J4+1) -> 2 | K5: =IF(I5=1000000,"","Sabit") -> Sabit
A6: OP_A020080_A | B6: OP_A020080_A_3 | C6: Oprt4 | D6: Oprt3 | H6: 1 | I6: =VLOOKUP(A6,İstasyonlar!$A$2:$D$776,4,0) -> 999999999 | J6: =IF(A6=A5, J5, J5+1) -> 2 | K6: =IF(I6=1000000,"","Sabit") -> Sabit
A7: OP_A020140 | B7: OP_A020140_1 | C7: Oprt93 | D7: Oprt16 | H7: 9.5 | I7: =VLOOKUP(A7,İstasyonlar!$A$2:$D$776,4,0) -> 1000000 | J7: =IF(A7=A6, J6, J6+1) -> 3 | K7: =IF(I7=1000000,"","Sabit")
A8: OP_A020140 | B8: OP_A020140_2 | C8: Oprt93 | D8: Oprt16 | H8: 3.1 | I8: =VLOOKUP(A8,İstasyonlar!$A$2:$D$776,4,0) -> 1000000 | J8: =IF(A8=A7, J7, J7+1) -> 3 | K8: =IF(I8=1000000,"","Sabit")
A9: OP_A020160 | B9: OP_A020160_1 | C9: Oprt67 | D9: Oprt22 | E9: Oprt11 | H9: 6.5 | I9: =VLOOKUP(A9,İstasyonlar!$A$2:$D$776,4,0) -> 1000000 | J9: =IF(A9=A8, J8, J8+1) -> 4 | K9: =IF(I9=1000000,"","Sabit")
A10: OP_A020160 | B10: OP_A020160_2 | C10: Oprt67 | D10: Oprt22 | E10: Oprt11 | H10: 3.1 | I10: =VLOOKUP(A10,İstasyonlar!$A$2:$D$776,4,0) -> 1000000 | J10: =IF(A10=A9, J9, J9+1) -> 4 | K10: =IF(I10=1000000,"","Sabit")
A11: OP_A020160 | B11: OP_A020160_3 | C11: Oprt67 | D11: Oprt22 | E11: Oprt11 | H11: 0.3 | I11: =VLOOKUP(A11,İstasyonlar!$A$2:$D$776,4,0) -> 1000000 | J11: =IF(A11=A10, J10, J10+1) -> 4 | K11: =IF(I11=1000000,"","Sabit")
A12: OP_A020190 | B12: OP_A020190_2 | C12: Oprt87 | D12: Oprt2 | E12: Oprt80 | H12: 2.37 | I12: =VLOOKUP(A12,İstasyonlar!$A$2:$D$776,4,0) -> 1000000 | J12: =IF(A12=A11, J11, J11+1) -> 5 | K12: =IF(I12=1000000,"","Sabit")
A13: OP_A020190 | B13: OP_A020190_3 | C13: Oprt87 | D13: Oprt2 | E13: Oprt80 | H13: 9.1 | I13: =VLOOKUP(A13,İstasyonlar!$A$2:$D$776,4,0) -> 1000000 | J13: =IF(A13=A12, J12, J12+1) -> 5 | K13: =IF(I13=1000000,"","Sabit")
A14: OP_A020190_A | B14: OP_A020190_A_1 | C14: Oprt80 | D14: Oprt87 | H14: 4.3 | I14: =VLOOKUP(A14,İstasyonlar!$A$2:$D$776,4,0) -> 1000000 | J14: =IF(A14=A13, J13, J13+1) -> 6 | K14: =IF(I14=1000000,"","Sabit")
A15: OP_A020190_A | B15: OP_A020190_A_2 | C15: Oprt80 | D15: Oprt87 | H15: 4.3 | I15: =VLOOKUP(A15,İstasyonlar!$A$2:$D$776,4,0) -> 1000000 | J15: =IF(A15=A14, J14, J14+1) -> 6 | K15: =IF(I15=1000000,"","Sabit")
A16: OP_A020300 | B16: OP_A020300_1 | C16: Oprt92 | D16: Oprt93 | H16: 5.3 | I16: =VLOOKUP(A16,İstasyonlar!$A$2:$D$776,4,0) -> 999999999 | J16: =IF(A16=A15, J15, J15+1) -> 7 | K16: =IF(I16=1000000,"","Sabit") -> Sabit
A17: OP_A020300 | B17: OP_A020300_2 | C17: Oprt92 | D17: Oprt93 | H17: 6.4 | I17: =VLOOKUP(A17,İstasyonlar!$A$2:$D$776,4,0) -> 999999999 | J17: =IF(A17=A16, J16, J16+1) -> 7 | K17: =IF(I17=1000000,"","Sabit") -> Sabit
A18: OP_A020300 | B18: OP_A020300_3 | C18: Oprt92 | D18: Oprt93 | H18: 2.4 | I18: =VLOOKUP(A18,İstasyonlar!$A$2:$D$776,4,0) -> 999999999 | J18: =IF(A18=A17, J17, J17+1) -> 7 | K18: =IF(I18=1000000,"","Sabit") -> Sabit
A19: OP_A020300 | B19: OP_A020300_4 | C19: Oprt92 | D19: Oprt93 | H19: 2.7 | I19: =VLOOKUP(A19,İstasyonlar!$A$2:$D$776,4,0) -> 999999999 | J19: =IF(A19=A18, J18, J18+1) -> 7 | K19: =IF(I19=1000000,"","Sabit") -> Sabit
A20: OP_A020330 | B20: OP_A020330_1 | C20: Oprt52 | D20: Oprt53 | G20: Oprt3 | H20: 9.2 | I20: =VLOOKUP(A20,İstasyonlar!$A$2:$D$776,4,0) -> 999999999 | J20: =IF(A20=A19, J19, J19+1) -> 8 | K20: =IF(I20=1000000,"","Sabit") -> Sabit
A21: OP_A020330 | B21: OP_A020330_2 | C21: Oprt52 | D21: Oprt53 | G21: Oprt3 | H21: 9.2 | I21: =VLOOKUP(A21,İstasyonlar!$A$2:$D$776,4,0) -> 999999999 | J21: =IF(A21=A20, J20, J20+1) -> 8 | K21: =IF(I21=1000000,"","Sabit") -> Sabit
A22: OP_A020330_A | B22: OP_A020330_A_1 | C22: Oprt53 | D22: Oprt52 | E22: Oprt92 | H22: 9.2 | I22: =VLOOKUP(A22,İstasyonlar!$A$2:$D$776,4,0) -> 999999999 | J22: =IF(A22=A21, J21, J21+1) -> 9 | K22: =IF(I22=1000000,"","Sabit") -> Sabit
A23: OP_A020330_A | B23: OP_A020330_A_2 | C23: Oprt53 | D23: Oprt52 | E23: Oprt92 | H23: 9.2 | I23: =VLOOKUP(A23,İstasyonlar!$A$2:$D$776,4,0) -> 999999999 | J23: =IF(A23=A22, J22, J22+1) -> 9 | K23: =IF(I23=1000000,"","Sabit") -> Sabit
A24: OP_A020350 | B24: OP_A020350_7 | C24: Oprt61 | H24: 5.5 | I24: =VLOOKUP(A24,İstasyonlar!$A$2:$D$776,4,0) -> 999999999 | J24: =IF(A24=A23, J23, J23+1) -> 10 | K24: =IF(I24=1000000,"","Sabit") -> Sabit
A25: OP_A020350 | B25: OP_A020350_10 | C25: Oprt61 | H25: 3.8 | I25: =VLOOKUP(A25,İstasyonlar!$A$2:$D$776,4,0) -> 999999999 | J25: =IF(A25=A24, J24, J24+1) -> 10 | K25: =IF(I25=1000000,"","Sabit") -> Sabit
A26: OP_A020350 | B26: OP_A020350_4 | C26: Oprt61 | H26: 2.5 | I26: =VLOOKUP(A26,İstasyonlar!$A$2:$D$776,4,0) -> 999999999 | J26: =IF(A26=A25, J25, J25+1) -> 10 | K26: =IF(I26=1000000,"","Sabit") -> Sabit
A27: OP_A020350 | B27: OP_A020350_5 | C27: Oprt61 | H27: 2.7 | I27: =VLOOKUP(A27,İstasyonlar!$A$2:$D$776,4,0) -> 999999999 | J27: =IF(A27=A26, J26, J26+1) -> 10 | K27: =IF(I27=1000000,"","Sabit") -> Sabit
A28: OP_A020390 | B28: OP_A020390_1 | C28: Oprt60 | D28: Oprt21 | H28: 3.9 | I28: =VLOOKUP(A28,İstasyonlar!$A$2:$D$776,4,0) -> 1000000 | J28: =IF(A28=A27, J27, J27+1) -> 11 | K28: =IF(I28=1000000,"","Sabit")
A29: OP_A020390 | B29: OP_A020390_2 | C29: Oprt60 | D29: Oprt21 | H29: 5.5 | I29: =VLOOKUP(A29,İstasyonlar!$A$2:$D$776,4,0) -> 1000000 | J29: =IF(A29=A28, J28, J28+1) -> 11 | K29: =IF(I29=1000000,"","Sabit")
A30: OP_A020390 | B30: OP_A020390_3 | C30: Oprt60 | D30: Oprt21 | H30: 7.2 | I30: =VLOOKUP(A30,İstasyonlar!$A$2:$D$776,4,0) -> 1000000 | J30: =IF(A30=A29, J29, J29+1) -> 11 | K30: =IF(I30=1000000,"","Sabit")
A31: OP_A020420 | B31: OP_A020420_1 | C31: Oprt27 | H31: 11.5 | I31: =VLOOKUP(A31,İstasyonlar!$A$2:$D$776,4,0) -> 1000000 | J31: =IF(A31=A30, J30, J30+1) -> 12 | K31: =IF(I31=1000000,"","Sabit")
A32: OP_A020450 | B32: OP_A020450_1 | C32: Oprt45 | D32: Oprt27 | H32: 6.2 | I32: =VLOOKUP(A32,İstasyonlar!$A$2:$D$776,4,0) -> 1000000 | J32: =IF(A32=A31, J31, J31+1) -> 13 | K32: =IF(I32=1000000,"","Sabit")
A33: OP_A020450 | B33: OP_A020450_2 | C33: Oprt45 | D33: Oprt27 | H33: 3.1 | I33: =VLOOKUP(A33,İstasyonlar!$A$2:$D$776,4,0) -> 1000000 | J33: =IF(A33=A32, J32, J32+1) -> 13 | K33: =IF(I33=1000000,"","Sabit")
A34: OP_A020480 | B34: OP_A020480_1 | C34: Oprt75 | H34: 3.2 | I34: =VLOOKUP(A34,İstasyonlar!$A$2:$D$776,4,0) -> 999999999 | J34: =IF(A34=A33, J33, J33+1) -> 14 | K34: =IF(I34=1000000,"","Sabit") -> Sabit
A35: OP_A020480 | B35: OP_A020480_2 | C35: Oprt75 | H35: 5.5 | I35: =VLOOKUP(A35,İstasyonlar!$A$2:$D$776,4,0) -> 999999999 | J35: =IF(A35=A34, J34, J34+1) -> 14 | K35: =IF(I35=1000000,"","Sabit") -> Sabit
A36: OP_A020480 | B36: OP_A020480_3 | C36: Oprt75 | H36: 5 | I36: =VLOOKUP(A36,İstasyonlar!$A$2:$D$776,4,0) -> 999999999 | J36: =IF(A36=A35, J35, J35+1) -> 14 | K36: =IF(I36=1000000,"","Sabit") -> Sabit
A37: OP_A020500 | B37: OP_A020500_1 | C37: Oprt28 | H37: 6 | I37: =VLOOKUP(A37,İstasyonlar!$A$2:$D$776,4,0) -> 999999999 | J37: =IF(A37=A36, J36, J36+1) -> 15 | K37: =IF(I37=1000000,"","Sabit") -> Sabit
A38: OP_A020500 | B38: OP_A020500_2 | C38: Oprt28 | H38: 3.1 | I38: =VLOOKUP(A38,İstasyonlar!$A$2:$D$776,4,0) -> 999999999 | J38: =IF(A38=A37, J37, J37+1) -> 15 | K38: =IF(I38=1000000,"","Sabit") -> Sabit
A39: OP_A020530 | B39: OP_A020530_3 | C39: Oprt84 | D39: Oprt80 | H39: 15.8 | I39: =VLOOKUP(A39,İstasyonlar!$A$2:$D$776,4,0) -> 999999999 | J39: =IF(A39=A38, J38, J38+1) -> 16 | K39: =IF(I39=1000000,"","Sabit") -> Sabit
A40: OP_A020570 | B40: OP_A020570_1 | C40: Oprt6 | D40: Oprt36 | E40: Oprt35 | H40: 2.1 | I40: =VLOOKUP(A40,İstasyonlar!$A$2:$D$776,4,0) -> 999999999 | J40: =IF(A40=A39, J39, J39+1) -> 17 | K40: =IF(I40=1000000,"","Sabit") -> Sabit
...

Sheet 78446 için istasyonlar
A1: İstasyon adres | B1: Operasyon No | C1: İstasyon Bilgisi Operatör 1 | D1: İstasyon Bilgisi Operatör 2 | E1: İstasyon Bilgisi Operatör 3 | F1: İstasyon Bilgisi Operatör 4 | G1: İstasyon Bilgisi Operatör 5 | H1: SÜRE (SN) | I1: Ceza | J1: Sıra
A2: OP_A020060 | B2: OP_A020060_1 | C2: Oprt15 | D2: Oprt11 | E2: Oprt3 | H2: 6.1 | I2: =VLOOKUP(A2,İstasyonlar!$A$2:$D$776,4,0) -> 1000000 | J2: 1 | K2: =IF(I2=1000000,"","Sabit")
A3: OP_A020060 | B3: OP_A020060_2 | C3: Oprt15 | D3: Oprt11 | E3: Oprt3 | H3: 6.1 | I3: =VLOOKUP(A3,İstasyonlar!$A$2:$D$776,4,0) -> 1000000 | J3: =IF(A3=A2, J2, J2+1) -> 1 | K3: =IF(I3=1000000,"","Sabit")
A4: OP_A020080 | B4: OP_A020080_1 | C4: Oprt3 | D4: Oprt4 | E4: Oprt15 | H4: 5.8 | I4: =VLOOKUP(A4,İstasyonlar!$A$2:$D$776,4,0) -> 999999999 | J4: =IF(A4=A3, J3, J3+1) -> 2 | K4: =IF(I4=1000000,"","Sabit") -> Sabit
A5: OP_A020080 | B5: OP_A020080_2 | C5: Oprt3 | D5: Oprt4 | E5: Oprt15 | H5: 6.4 | I5: =VLOOKUP(A5,İstasyonlar!$A$2:$D$776,4,0) -> 999999999 | J5: =IF(A5=A4, J4, J4+1) -> 2 | K5: =IF(I5=1000000,"","Sabit") -> Sabit
A6: OP_A020080_A | B6: OP_A020080_A_2 | C6: Oprt4 | D6: Oprt3 | H6: 6.4 | I6: =VLOOKUP(A6,İstasyonlar!$A$2:$D$776,4,0) -> 999999999 | J6: =IF(A6=A5, J5, J5+1) -> 3 | K6: =IF(I6=1000000,"","Sabit") -> Sabit
A7: OP_A020080_A | B7: OP_A020080_A_3 | C7: Oprt4 | D7: Oprt3 | H7: 1 | I7: =VLOOKUP(A7,İstasyonlar!$A$2:$D$776,4,0) -> 999999999 | J7: =IF(A7=A6, J6, J6+1) -> 3 | K7: =IF(I7=1000000,"","Sabit") -> Sabit
A8: OP_A020140 | B8: OP_A020140_1 | C8: Oprt93 | D8: Oprt16 | H8: 9.5 | I8: =VLOOKUP(A8,İstasyonlar!$A$2:$D$776,4,0) -> 1000000 | J8: =IF(A8=A7, J7, J7+1) -> 4 | K8: =IF(I8=1000000,"","Sabit")
A9: OP_A020140 | B9: OP_A020140_2 | C9: Oprt93 | D9: Oprt16 | H9: 3.1 | I9: =VLOOKUP(A9,İstasyonlar!$A$2:$D$776,4,0) -> 1000000 | J9: =IF(A9=A8, J8, J8+1) -> 4 | K9: =IF(I9=1000000,"","Sabit")
A10: OP_A020160 | B10: OP_A020160_1 | C10: Oprt67 | D10: Oprt22 | E10: Oprt11 | H10: 6.5 | I10: =VLOOKUP(A10,İstasyonlar!$A$2:$D$776,4,0) -> 1000000 | J10: =IF(A10=A9, J9, J9+1) -> 5 | K10: =IF(I10=1000000,"","Sabit")
A11: OP_A020160 | B11: OP_A020160_2 | C11: Oprt67 | D11: Oprt22 | E11: Oprt11 | H11: 3.1 | I11: =VLOOKUP(A11,İstasyonlar!$A$2:$D$776,4,0) -> 1000000 | J11: =IF(A11=A10, J10, J10+1) -> 5 | K11: =IF(I11=1000000,"","Sabit")
A12: OP_A020160 | B12: OP_A020160_3 | C12: Oprt67 | D12: Oprt22 | E12: Oprt11 | H12: 0.3 | I12: =VLOOKUP(A12,İstasyonlar!$A$2:$D$776,4,0) -> 1000000 | J12: =IF(A12=A11, J11, J11+1) -> 5 | K12: =IF(I12=1000000,"","Sabit")
A13: OP_A020220 | B13: OP_A020220_1 | C13: Oprt11 | E13: Oprt69 | F13: Oprt3 | H13: 6.5 | I13: =VLOOKUP(A13,İstasyonlar!$A$2:$D$776,4,0) -> 1000000 | J13: =IF(A13=A12, J12, J12+1) -> 6 | K13: =IF(I13=1000000,"","Sabit")
A14: OP_A020220 | B14: OP_A020220_2 | C14: Oprt11 | E14: Oprt69 | F14: Oprt3 | H14: 2.8 | I14: =VLOOKUP(A14,İstasyonlar!$A$2:$D$776,4,0) -> 1000000 | J14: =IF(A14=A13, J13, J13+1) -> 6 | K14: =IF(I14=1000000,"","Sabit")
A15: OP_A020220 | B15: OP_A020220_3 | C15: Oprt11 | E15: Oprt69 | F15: Oprt3 | H15: 3.1 | I15: =VLOOKUP(A15,İstasyonlar!$A$2:$D$776,4,0) -> 1000000 | J15: =IF(A15=A14, J14, J14+1) -> 6 | K15: =IF(I15=1000000,"","Sabit")
A16: OP_A020190_A | B16: OP_A020190_A_3 | C16: Oprt80 | D16: Oprt87 | H16: 4.3 | I16: =VLOOKUP(A16,İstasyonlar!$A$2:$D$776,4,0) -> 1000000 | J16: =IF(A16=A15, J15, J15+1) -> 7 | K16: =IF(I16=1000000,"","Sabit")
A17: OP_A020300 | B17: OP_A020300_1 | C17: Oprt92 | D17: Oprt93 | H17: 5.3 | I17: =VLOOKUP(A17,İstasyonlar!$A$2:$D$776,4,0) -> 999999999 | J17: =IF(A17=A16, J16, J16+1) -> 8 | K17: =IF(I17=1000000,"","Sabit") -> Sabit
A18: OP_A020300 | B18: OP_A020300_2 | C18: Oprt92 | D18: Oprt93 | H18: 6.4 | I18: =VLOOKUP(A18,İstasyonlar!$A$2:$D$776,4,0) -> 999999999 | J18: =IF(A18=A17, J17, J17+1) -> 8 | K18: =IF(I18=1000000,"","Sabit") -> Sabit
A19: OP_A020300 | B19: OP_A020300_3 | C19: Oprt92 | D19: Oprt93 | H19: 2.4 | I19: =VLOOKUP(A19,İstasyonlar!$A$2:$D$776,4,0) -> 999999999 | J19: =IF(A19=A18, J18, J18+1) -> 8 | K19: =IF(I19=1000000,"","Sabit") -> Sabit
A20: OP_A020300 | B20: OP_A020300_4 | C20: Oprt92 | D20: Oprt93 | H20: 2.7 | I20: =VLOOKUP(A20,İstasyonlar!$A$2:$D$776,4,0) -> 999999999 | J20: =IF(A20=A19, J19, J19+1) -> 8 | K20: =IF(I20=1000000,"","Sabit") -> Sabit
A21: OP_A020330 | B21: OP_A020330_1 | C21: Oprt52 | D21: Oprt53 | G21: Oprt3 | H21: 9.2 | I21: =VLOOKUP(A21,İstasyonlar!$A$2:$D$776,4,0) -> 999999999 | J21: =IF(A21=A20, J20, J20+1) -> 9 | K21: =IF(I21=1000000,"","Sabit") -> Sabit
A22: OP_A020330 | B22: OP_A020330_2 | C22: Oprt52 | D22: Oprt53 | G22: Oprt3 | H22: 9.2 | I22: =VLOOKUP(A22,İstasyonlar!$A$2:$D$776,4,0) -> 999999999 | J22: =IF(A22=A21, J21, J21+1) -> 9 | K22: =IF(I22=1000000,"","Sabit") -> Sabit
A23: OP_A020330_A | B23: OP_A020330_A_1 | C23: Oprt53 | D23: Oprt52 | E23: Oprt92 | H23: 9.2 | I23: =VLOOKUP(A23,İstasyonlar!$A$2:$D$776,4,0) -> 999999999 | J23: =IF(A23=A22, J22, J22+1) -> 10 | K23: =IF(I23=1000000,"","Sabit") -> Sabit
A24: OP_A020330_A | B24: OP_A020330_A_2 | C24: Oprt53 | D24: Oprt52 | E24: Oprt92 | H24: 9.2 | I24: =VLOOKUP(A24,İstasyonlar!$A$2:$D$776,4,0) -> 999999999 | J24: =IF(A24=A23, J23, J23+1) -> 10 | K24: =IF(I24=1000000,"","Sabit") -> Sabit
A25: OP_A020350 | B25: OP_A020350_7 | C25: Oprt61 | H25: 5.5 | I25: =VLOOKUP(A25,İstasyonlar!$A$2:$D$776,4,0) -> 999999999 | J25: =IF(A25=A24, J24, J24+1) -> 11 | K25: =IF(I25=1000000,"","Sabit") -> Sabit
A26: OP_A020350 | B26: OP_A020350_8 | C26: Oprt61 | H26: 3.1 | I26: =VLOOKUP(A26,İstasyonlar!$A$2:$D$776,4,0) -> 999999999 | J26: =IF(A26=A25, J25, J25+1) -> 11 | K26: =IF(I26=1000000,"","Sabit") -> Sabit
A27: OP_A020350 | B27: OP_A020350_9 | C27: Oprt61 | H27: 4.5 | I27: =VLOOKUP(A27,İstasyonlar!$A$2:$D$776,4,0) -> 999999999 | J27: =IF(A27=A26, J26, J26+1) -> 11 | K27: =IF(I27=1000000,"","Sabit") -> Sabit
A28: OP_A020350 | B28: OP_A020350_5 | C28: Oprt61 | H28: 2.7 | I28: =VLOOKUP(A28,İstasyonlar!$A$2:$D$776,4,0) -> 999999999 | J28: =IF(A28=A27, J27, J27+1) -> 11 | K28: =IF(I28=1000000,"","Sabit") -> Sabit
A29: OP_A020390 | B29: OP_A020390_1 | C29: Oprt60 | D29: Oprt21 | H29: 3.9 | I29: =VLOOKUP(A29,İstasyonlar!$A$2:$D$776,4,0) -> 1000000 | J29: =IF(A29=A28, J28, J28+1) -> 12 | K29: =IF(I29=1000000,"","Sabit")
A30: OP_A020390 | B30: OP_A020390_2 | C30: Oprt60 | D30: Oprt21 | H30: 5.5 | I30: =VLOOKUP(A30,İstasyonlar!$A$2:$D$776,4,0) -> 1000000 | J30: =IF(A30=A29, J29, J29+1) -> 12 | K30: =IF(I30=1000000,"","Sabit")
A31: OP_A020390 | B31: OP_A020390_3 | C31: Oprt60 | D31: Oprt21 | H31: 7.2 | I31: =VLOOKUP(A31,İstasyonlar!$A$2:$D$776,4,0) -> 1000000 | J31: =IF(A31=A30, J30, J30+1) -> 12 | K31: =IF(I31=1000000,"","Sabit")
A32: OP_A020420 | B32: OP_A020420_1 | C32: Oprt27 | H32: 11.5 | I32: =VLOOKUP(A32,İstasyonlar!$A$2:$D$776,4,0) -> 1000000 | J32: =IF(A32=A31, J31, J31+1) -> 13 | K32: =IF(I32=1000000,"","Sabit")
A33: OP_A020450 | B33: OP_A020450_1 | C33: Oprt45 | D33: Oprt27 | H33: 6.2 | I33: =VLOOKUP(A33,İstasyonlar!$A$2:$D$776,4,0) -> 1000000 | J33: =IF(A33=A32, J32, J32+1) -> 14 | K33: =IF(I33=1000000,"","Sabit")
A34: OP_A020450 | B34: OP_A020450_2 | C34: Oprt45 | D34: Oprt27 | H34: 3.1 | I34: =VLOOKUP(A34,İstasyonlar!$A$2:$D$776,4,0) -> 1000000 | J34: =IF(A34=A33, J33, J33+1) -> 14 | K34: =IF(I34=1000000,"","Sabit")
A35: OP_A020480 | B35: OP_A020480_1 | C35: Oprt75 | H35: 3.2 | I35: =VLOOKUP(A35,İstasyonlar!$A$2:$D$776,4,0) -> 999999999 | J35: =IF(A35=A34, J34, J34+1) -> 15 | K35: =IF(I35=1000000,"","Sabit") -> Sabit
A36: OP_A020480 | B36: OP_A020480_2 | C36: Oprt75 | H36: 5.5 | I36: =VLOOKUP(A36,İstasyonlar!$A$2:$D$776,4,0) -> 999999999 | J36: =IF(A36=A35, J35, J35+1) -> 15 | K36: =IF(I36=1000000,"","Sabit") -> Sabit
A37: OP_A020480 | B37: OP_A020480_3 | C37: Oprt75 | H37: 5 | I37: =VLOOKUP(A37,İstasyonlar!$A$2:$D$776,4,0) -> 999999999 | J37: =IF(A37=A36, J36, J36+1) -> 15 | K37: =IF(I37=1000000,"","Sabit") -> Sabit
A38: OP_A020500 | B38: OP_A020500_1 | C38: Oprt28 | H38: 6 | I38: =VLOOKUP(A38,İstasyonlar!$A$2:$D$776,4,0) -> 999999999 | J38: =IF(A38=A37, J37, J37+1) -> 16 | K38: =IF(I38=1000000,"","Sabit") -> Sabit
A39: OP_A020500 | B39: OP_A020500_3 | C39: Oprt28 | H39: 8.1 | I39: =VLOOKUP(A39,İstasyonlar!$A$2:$D$776,4,0) -> 999999999 | J39: =IF(A39=A38, J38, J38+1) -> 16 | K39: =IF(I39=1000000,"","Sabit") -> Sabit
A40: OP_A020500 | B40: OP_A020500_4 | C40: Oprt28 | H40: 3.8 | I40: =VLOOKUP(A40,İstasyonlar!$A$2:$D$776,4,0) -> 999999999 | J40: =IF(A40=A39, J39, J39+1) -> 16 | K40: =IF(I40=1000000,"","Sabit") -> Sabit
...

Sheet 40132 için istasyonlar
A1: İstasyon adres | B1: Operasyon No | C1: İstasyon Bilgisi Operatör 1 | D1: İstasyon Bilgisi Operatör 2 | E1: İstasyon Bilgisi Operatör 3 | F1: İstasyon Bilgisi Operatör 4 | G1: İstasyon Bilgisi Operatör 5 | H1: SÜRE (SN) | I1: Ceza | J1: Sıra
A2: OP_A020060 | B2: OP_A020060_1 | C2: Oprt15 | D2: Oprt11 | E2: Oprt3 | H2: 6.1 | I2: =VLOOKUP(A2,İstasyonlar!$A$2:$D$776,4,0) -> 1000000 | J2: 1 | K2: =IF(I2=1000000,"","Sabit") | M2: 1000000
A3: OP_A020060 | B3: OP_A020060_2 | C3: Oprt15 | D3: Oprt11 | E3: Oprt3 | H3: 6.1 | I3: =VLOOKUP(A3,İstasyonlar!$A$2:$D$776,4,0) -> 1000000 | J3: =IF(A3=A2, J2, J2+1) -> 1 | K3: =IF(I3=1000000,"","Sabit")
A4: OP_A020080 | B4: OP_A020080_1 | C4: Oprt3 | D4: Oprt4 | E4: Oprt15 | H4: 5.8 | I4: =VLOOKUP(A4,İstasyonlar!$A$2:$D$776,4,0) -> 999999999 | J4: =IF(A4=A3, J3, J3+1) -> 2 | K4: =IF(I4=1000000,"","Sabit") -> Sabit
A5: OP_A020080 | B5: OP_A020080_2 | C5: Oprt3 | D5: Oprt4 | E5: Oprt15 | H5: 6.4 | I5: =VLOOKUP(A5,İstasyonlar!$A$2:$D$776,4,0) -> 999999999 | J5: =IF(A5=A4, J4, J4+1) -> 2 | K5: =IF(I5=1000000,"","Sabit") -> Sabit
A6: OP_A020080_A | B6: OP_A020080_A_1 | C6: Oprt4 | D6: Oprt3 | H6: 6.1 | I6: =VLOOKUP(A6,İstasyonlar!$A$2:$D$776,4,0) -> 999999999 | J6: =IF(A6=A5, J5, J5+1) -> 3 | K6: =IF(I6=1000000,"","Sabit") -> Sabit
A7: OP_A020080_A | B7: OP_A020080_A_4 | C7: Oprt4 | D7: Oprt3 | H7: 2.8 | I7: =VLOOKUP(A7,İstasyonlar!$A$2:$D$776,4,0) -> 999999999 | J7: =IF(A7=A6, J6, J6+1) -> 3 | K7: =IF(I7=1000000,"","Sabit") -> Sabit
A8: OP_A020080_A | B8: OP_A020080_A_2 | C8: Oprt4 | D8: Oprt3 | H8: 6.4 | I8: =VLOOKUP(A8,İstasyonlar!$A$2:$D$776,4,0) -> 999999999 | J8: =IF(A8=A7, J7, J7+1) -> 3 | K8: =IF(I8=1000000,"","Sabit") -> Sabit
A9: OP_A020080_A | B9: OP_A020080_A_3 | C9: Oprt4 | D9: Oprt3 | H9: 1 | I9: =VLOOKUP(A9,İstasyonlar!$A$2:$D$776,4,0) -> 999999999 | J9: =IF(A9=A8, J8, J8+1) -> 3 | K9: =IF(I9=1000000,"","Sabit") -> Sabit
A10: OP_A020140 | B10: OP_A020140_1 | C10: Oprt93 | D10: Oprt16 | H10: 9.5 | I10: =VLOOKUP(A10,İstasyonlar!$A$2:$D$776,4,0) -> 1000000 | J10: =IF(A10=A9, J9, J9+1) -> 4 | K10: =IF(I10=1000000,"","Sabit")
A11: OP_A020140 | B11: OP_A020140_2 | C11: Oprt93 | D11: Oprt16 | H11: 3.1 | I11: =VLOOKUP(A11,İstasyonlar!$A$2:$D$776,4,0) -> 1000000 | J11: =IF(A11=A10, J10, J10+1) -> 4 | K11: =IF(I11=1000000,"","Sabit")
A12: OP_A020160 | B12: OP_A020160_4 | C12: Oprt67 | D12: Oprt22 | E12: Oprt11 | H12: 4.1 | I12: =VLOOKUP(A12,İstasyonlar!$A$2:$D$776,4,0) -> 1000000 | J12: =IF(A12=A11, J11, J11+1) -> 5 | K12: =IF(I12=1000000,"","Sabit")
A13: OP_A020160 | B13: OP_A020160_1 | C13: Oprt67 | D13: Oprt22 | E13: Oprt11 | H13: 6.5 | I13: =VLOOKUP(A13,İstasyonlar!$A$2:$D$776,4,0) -> 1000000 | J13: =IF(A13=A12, J12, J12+1) -> 5 | K13: =IF(I13=1000000,"","Sabit")
A14: OP_A020160 | B14: OP_A020160_2 | C14: Oprt67 | D14: Oprt22 | E14: Oprt11 | H14: 3.1 | I14: =VLOOKUP(A14,İstasyonlar!$A$2:$D$776,4,0) -> 1000000 | J14: =IF(A14=A13, J13, J13+1) -> 5 | K14: =IF(I14=1000000,"","Sabit")
A15: OP_A020160 | B15: OP_A020160_3 | C15: Oprt67 | D15: Oprt22 | E15: Oprt11 | H15: 0.3 | I15: =VLOOKUP(A15,İstasyonlar!$A$2:$D$776,4,0) -> 1000000 | J15: =IF(A15=A14, J14, J14+1) -> 5 | K15: =IF(I15=1000000,"","Sabit")
A16: OP_A020190 | B16: OP_A020190_2 | C16: Oprt87 | D16: Oprt2 | E16: Oprt80 | H16: 2.37 | I16: =VLOOKUP(A16,İstasyonlar!$A$2:$D$776,4,0) -> 1000000 | J16: =IF(A16=A15, J15, J15+1) -> 6 | K16: =IF(I16=1000000,"","Sabit")
A17: OP_A020190_A | B17: OP_A020190_A_3 | C17: Oprt80 | D17: Oprt87 | H17: 4.3 | I17: =VLOOKUP(A17,İstasyonlar!$A$2:$D$776,4,0) -> 1000000 | J17: =IF(A17=A16, J16, J16+1) -> 7 | K17: =IF(I17=1000000,"","Sabit")
A18: OP_A020220 | B18: OP_A020220_4 | C18: Oprt11 | E18: Oprt69 | F18: Oprt3 | H18: 3.1 | I18: =VLOOKUP(A18,İstasyonlar!$A$2:$D$776,4,0) -> 1000000 | J18: =IF(A18=A17, J17, J17+1) -> 8 | K18: =IF(I18=1000000,"","Sabit")
A19: OP_A020220 | B19: OP_A020220_1 | C19: Oprt11 | E19: Oprt69 | F19: Oprt3 | H19: 6.5 | I19: =VLOOKUP(A19,İstasyonlar!$A$2:$D$776,4,0) -> 1000000 | J19: =IF(A19=A18, J18, J18+1) -> 8 | K19: =IF(I19=1000000,"","Sabit")
A20: OP_A020220 | B20: OP_A020220_2 | C20: Oprt11 | E20: Oprt69 | F20: Oprt3 | H20: 2.8 | I20: =VLOOKUP(A20,İstasyonlar!$A$2:$D$776,4,0) -> 1000000 | J20: =IF(A20=A19, J19, J19+1) -> 8 | K20: =IF(I20=1000000,"","Sabit")
A21: OP_A020220 | B21: OP_A020220_3 | C21: Oprt11 | E21: Oprt69 | F21: Oprt3 | H21: 3.1 | I21: =VLOOKUP(A21,İstasyonlar!$A$2:$D$776,4,0) -> 1000000 | J21: =IF(A21=A20, J20, J20+1) -> 8 | K21: =IF(I21=1000000,"","Sabit")
A22: OP_A020210 | B22: OP_A020210_1 | C22: Oprt26 | H22: 6.1 | I22: =VLOOKUP(A22,İstasyonlar!$A$2:$D$776,4,0) -> 999999999 | J22: =IF(A22=A21, J21, J21+1) -> 9 | K22: =IF(I22=1000000,"","Sabit") -> Sabit
A23: OP_A020210 | B23: OP_A020210_2 | C23: Oprt26 | H23: 3.8 | I23: =VLOOKUP(A23,İstasyonlar!$A$2:$D$776,4,0) -> 999999999 | J23: =IF(A23=A22, J22, J22+1) -> 9 | K23: =IF(I23=1000000,"","Sabit") -> Sabit
A24: OP_A020210 | B24: OP_A020210_3 | C24: Oprt26 | H24: 2.8 | I24: =VLOOKUP(A24,İstasyonlar!$A$2:$D$776,4,0) -> 999999999 | J24: =IF(A24=A23, J23, J23+1) -> 9 | K24: =IF(I24=1000000,"","Sabit") -> Sabit
A25: OP_A020210 | B25: OP_A020210_4 | C25: Oprt26 | H25: 2.8 | I25: =VLOOKUP(A25,İstasyonlar!$A$2:$D$776,4,0) -> 999999999 | J25: =IF(A25=A24, J24, J24+1) -> 9 | K25: =IF(I25=1000000,"","Sabit") -> Sabit
A26: OP_A020210 | B26: OP_A020210_5 | C26: Oprt26 | H26: 3.1 | I26: =VLOOKUP(A26,İstasyonlar!$A$2:$D$776,4,0) -> 999999999 | J26: =IF(A26=A25, J25, J25+1) -> 9 | K26: =IF(I26=1000000,"","Sabit") -> Sabit
A27: OP_A020210 | B27: OP_A020210_6 | C27: Oprt26 | H27: 4.3 | I27: =VLOOKUP(A27,İstasyonlar!$A$2:$D$776,4,0) -> 999999999 | J27: =IF(A27=A26, J26, J26+1) -> 9 | K27: =IF(I27=1000000,"","Sabit") -> Sabit
A28: OP_A020210 | B28: OP_A020210_7 | C28: Oprt26 | H28: 4.1 | I28: =VLOOKUP(A28,İstasyonlar!$A$2:$D$776,4,0) -> 999999999 | J28: =IF(A28=A27, J27, J27+1) -> 9 | K28: =IF(I28=1000000,"","Sabit") -> Sabit
A29: OP_A020210 | B29: OP_A020210_8 | C29: Oprt26 | H29: 3.2 | I29: =VLOOKUP(A29,İstasyonlar!$A$2:$D$776,4,0) -> 999999999 | J29: =IF(A29=A28, J28, J28+1) -> 9 | K29: =IF(I29=1000000,"","Sabit") -> Sabit
A30: OP_A020210 | B30: OP_A020210_9 | C30: Oprt26 | H30: 1 | I30: =VLOOKUP(A30,İstasyonlar!$A$2:$D$776,4,0) -> 999999999 | J30: =IF(A30=A29, J29, J29+1) -> 9 | K30: =IF(I30=1000000,"","Sabit") -> Sabit
A31: OP_A020300 | B31: OP_A020300_1 | C31: Oprt92 | D31: Oprt93 | H31: 5.3 | I31: =VLOOKUP(A31,İstasyonlar!$A$2:$D$776,4,0) -> 999999999 | J31: =IF(A31=A30, J30, J30+1) -> 10 | K31: =IF(I31=1000000,"","Sabit") -> Sabit
A32: OP_A020300 | B32: OP_A020300_2 | C32: Oprt92 | D32: Oprt93 | H32: 6.4 | I32: =VLOOKUP(A32,İstasyonlar!$A$2:$D$776,4,0) -> 999999999 | J32: =IF(A32=A31, J31, J31+1) -> 10 | K32: =IF(I32=1000000,"","Sabit") -> Sabit
A33: OP_A020300 | B33: OP_A020300_3 | C33: Oprt92 | D33: Oprt93 | H33: 2.4 | I33: =VLOOKUP(A33,İstasyonlar!$A$2:$D$776,4,0) -> 999999999 | J33: =IF(A33=A32, J32, J32+1) -> 10 | K33: =IF(I33=1000000,"","Sabit") -> Sabit
A34: OP_A020300 | B34: OP_A020300_4 | C34: Oprt92 | D34: Oprt93 | H34: 2.7 | I34: =VLOOKUP(A34,İstasyonlar!$A$2:$D$776,4,0) -> 999999999 | J34: =IF(A34=A33, J33, J33+1) -> 10 | K34: =IF(I34=1000000,"","Sabit") -> Sabit
A35: OP_A020330 | B35: OP_A020330_1 | C35: Oprt52 | D35: Oprt53 | G35: Oprt3 | H35: 9.2 | I35: =VLOOKUP(A35,İstasyonlar!$A$2:$D$776,4,0) -> 999999999 | J35: =IF(A35=A34, J34, J34+1) -> 11 | K35: =IF(I35=1000000,"","Sabit") -> Sabit
A36: OP_A020330 | B36: OP_A020330_2 | C36: Oprt52 | D36: Oprt53 | G36: Oprt3 | H36: 9.2 | I36: =VLOOKUP(A36,İstasyonlar!$A$2:$D$776,4,0) -> 999999999 | J36: =IF(A36=A35, J35, J35+1) -> 11 | K36: =IF(I36=1000000,"","Sabit") -> Sabit
A37: OP_A020330 | B37: OP_A020330_3 | C37: Oprt52 | D37: Oprt53 | G37: Oprt3 | H37: 9.2 | I37: =VLOOKUP(A37,İstasyonlar!$A$2:$D$776,4,0) -> 999999999 | J37: =IF(A37=A36, J36, J36+1) -> 11 | K37: =IF(I37=1000000,"","Sabit") -> Sabit
A38: OP_A020330 | B38: OP_A020330_4 | C38: Oprt52 | D38: Oprt53 | G38: Oprt3 | H38: 9.2 | I38: =VLOOKUP(A38,İstasyonlar!$A$2:$D$776,4,0) -> 999999999 | J38: =IF(A38=A37, J37, J37+1) -> 11 | K38: =IF(I38=1000000,"","Sabit") -> Sabit
A39: OP_A020330_A | B39: OP_A020330_A_1 | C39: Oprt53 | D39: Oprt52 | E39: Oprt92 | H39: 9.2 | I39: =VLOOKUP(A39,İstasyonlar!$A$2:$D$776,4,0) -> 999999999 | J39: =IF(A39=A38, J38, J38+1) -> 12 | K39: =IF(I39=1000000,"","Sabit") -> Sabit
A40: OP_A020330_A | B40: OP_A020330_A_2 | C40: Oprt53 | D40: Oprt52 | E40: Oprt92 | H40: 9.2 | I40: =VLOOKUP(A40,İstasyonlar!$A$2:$D$776,4,0) -> 999999999 | J40: =IF(A40=A39, J39, J39+1) -> 12 | K40: =IF(I40=1000000,"","Sabit") -> Sabit
...

Sheet 77558 için istasyonlar
A1: İstasyon adres | B1: Operasyon No | C1: İstasyon Bilgisi Operatör 1 | D1: İstasyon Bilgisi Operatör 2 | E1: İstasyon Bilgisi Operatör 3 | F1: İstasyon Bilgisi Operatör 4 | G1: İstasyon Bilgisi Operatör 5 | H1: SÜRE (SN) | I1: Ceza | J1: Sıra
A2: OP_A020060 | B2: OP_A020060_1 | C2: Oprt15 | D2: Oprt11 | E2: Oprt3 | H2: 6.1 | I2: =VLOOKUP(A2,İstasyonlar!$A$2:$D$776,4,0) -> 1000000 | J2: 1 | K2: =IF(I2=1000000,"","Sabit")
A3: OP_A020060 | B3: OP_A020060_2 | C3: Oprt15 | D3: Oprt11 | E3: Oprt3 | H3: 6.1 | I3: =VLOOKUP(A3,İstasyonlar!$A$2:$D$776,4,0) -> 1000000 | J3: =IF(A3=A2, J2, J2+1) -> 1 | K3: =IF(I3=1000000,"","Sabit")
A4: OP_A020080 | B4: OP_A020080_1 | C4: Oprt3 | D4: Oprt4 | E4: Oprt15 | H4: 5.8 | I4: =VLOOKUP(A4,İstasyonlar!$A$2:$D$776,4,0) -> 999999999 | J4: =IF(A4=A3, J3, J3+1) -> 2 | K4: =IF(I4=1000000,"","Sabit") -> Sabit
A5: OP_A020080 | B5: OP_A020080_2 | C5: Oprt3 | D5: Oprt4 | E5: Oprt15 | H5: 6.4 | I5: =VLOOKUP(A5,İstasyonlar!$A$2:$D$776,4,0) -> 999999999 | J5: =IF(A5=A4, J4, J4+1) -> 2 | K5: =IF(I5=1000000,"","Sabit") -> Sabit
A6: OP_A020080_A | B6: OP_A020080_A_1 | C6: Oprt4 | D6: Oprt3 | H6: 6.1 | I6: =VLOOKUP(A6,İstasyonlar!$A$2:$D$776,4,0) -> 999999999 | J6: =IF(A6=A5, J5, J5+1) -> 3 | K6: =IF(I6=1000000,"","Sabit") -> Sabit
A7: OP_A020080_A | B7: OP_A020080_A_2 | C7: Oprt4 | D7: Oprt3 | H7: 6.4 | I7: =VLOOKUP(A7,İstasyonlar!$A$2:$D$776,4,0) -> 999999999 | J7: =IF(A7=A6, J6, J6+1) -> 3 | K7: =IF(I7=1000000,"","Sabit") -> Sabit
A8: OP_A020080_A | B8: OP_A020080_A_3 | C8: Oprt4 | D8: Oprt3 | H8: 1 | I8: =VLOOKUP(A8,İstasyonlar!$A$2:$D$776,4,0) -> 999999999 | J8: =IF(A8=A7, J7, J7+1) -> 3 | K8: =IF(I8=1000000,"","Sabit") -> Sabit
A9: OP_A020140 | B9: OP_A020140_1 | C9: Oprt93 | D9: Oprt16 | H9: 9.5 | I9: =VLOOKUP(A9,İstasyonlar!$A$2:$D$776,4,0) -> 1000000 | J9: =IF(A9=A8, J8, J8+1) -> 4 | K9: =IF(I9=1000000,"","Sabit")
A10: OP_A020140 | B10: OP_A020140_2 | C10: Oprt93 | D10: Oprt16 | H10: 3.1 | I10: =VLOOKUP(A10,İstasyonlar!$A$2:$D$776,4,0) -> 1000000 | J10: =IF(A10=A9, J9, J9+1) -> 4 | K10: =IF(I10=1000000,"","Sabit")
A11: OP_A020160 | B11: OP_A020160_1 | C11: Oprt67 | D11: Oprt22 | E11: Oprt11 | H11: 6.5 | I11: =VLOOKUP(A11,İstasyonlar!$A$2:$D$776,4,0) -> 1000000 | J11: =IF(A11=A10, J10, J10+1) -> 5 | K11: =IF(I11=1000000,"","Sabit")
A12: OP_A020160 | B12: OP_A020160_2 | C12: Oprt67 | D12: Oprt22 | E12: Oprt11 | H12: 3.1 | I12: =VLOOKUP(A12,İstasyonlar!$A$2:$D$776,4,0) -> 1000000 | J12: =IF(A12=A11, J11, J11+1) -> 5 | K12: =IF(I12=1000000,"","Sabit")
A13: OP_A020160 | B13: OP_A020160_3 | C13: Oprt67 | D13: Oprt22 | E13: Oprt11 | H13: 0.3 | I13: =VLOOKUP(A13,İstasyonlar!$A$2:$D$776,4,0) -> 1000000 | J13: =IF(A13=A12, J12, J12+1) -> 5 | K13: =IF(I13=1000000,"","Sabit")
A14: OP_A020190 | B14: OP_A020190_2 | C14: Oprt87 | D14: Oprt2 | E14: Oprt80 | H14: 2.37 | I14: =VLOOKUP(A14,İstasyonlar!$A$2:$D$776,4,0) -> 1000000 | J14: =IF(A14=A13, J13, J13+1) -> 6 | K14: =IF(I14=1000000,"","Sabit")
A15: OP_A020190 | B15: OP_A020190_3 | C15: Oprt87 | D15: Oprt2 | E15: Oprt80 | H15: 9.1 | I15: =VLOOKUP(A15,İstasyonlar!$A$2:$D$776,4,0) -> 1000000 | J15: =IF(A15=A14, J14, J14+1) -> 6 | K15: =IF(I15=1000000,"","Sabit")
A16: OP_A020190_A | B16: OP_A020190_A_3 | C16: Oprt80 | D16: Oprt87 | H16: 4.3 | I16: =VLOOKUP(A16,İstasyonlar!$A$2:$D$776,4,0) -> 1000000 | J16: =IF(A16=A15, J15, J15+1) -> 7 | K16: =IF(I16=1000000,"","Sabit")
A17: OP_A020300 | B17: OP_A020300_1 | C17: Oprt92 | D17: Oprt93 | H17: 5.3 | I17: =VLOOKUP(A17,İstasyonlar!$A$2:$D$776,4,0) -> 999999999 | J17: =IF(A17=A16, J16, J16+1) -> 8 | K17: =IF(I17=1000000,"","Sabit") -> Sabit
A18: OP_A020300 | B18: OP_A020300_2 | C18: Oprt92 | D18: Oprt93 | H18: 6.4 | I18: =VLOOKUP(A18,İstasyonlar!$A$2:$D$776,4,0) -> 999999999 | J18: =IF(A18=A17, J17, J17+1) -> 8 | K18: =IF(I18=1000000,"","Sabit") -> Sabit
A19: OP_A020300 | B19: OP_A020300_3 | C19: Oprt92 | D19: Oprt93 | H19: 2.4 | I19: =VLOOKUP(A19,İstasyonlar!$A$2:$D$776,4,0) -> 999999999 | J19: =IF(A19=A18, J18, J18+1) -> 8 | K19: =IF(I19=1000000,"","Sabit") -> Sabit
A20: OP_A020300 | B20: OP_A020300_4 | C20: Oprt92 | D20: Oprt93 | H20: 2.7 | I20: =VLOOKUP(A20,İstasyonlar!$A$2:$D$776,4,0) -> 999999999 | J20: =IF(A20=A19, J19, J19+1) -> 8 | K20: =IF(I20=1000000,"","Sabit") -> Sabit
A21: OP_A020330 | B21: OP_A020330_1 | C21: Oprt52 | D21: Oprt53 | G21: Oprt3 | H21: 9.2 | I21: =VLOOKUP(A21,İstasyonlar!$A$2:$D$776,4,0) -> 999999999 | J21: =IF(A21=A20, J20, J20+1) -> 9 | K21: =IF(I21=1000000,"","Sabit") -> Sabit
A22: OP_A020330 | B22: OP_A020330_2 | C22: Oprt52 | D22: Oprt53 | G22: Oprt3 | H22: 9.2 | I22: =VLOOKUP(A22,İstasyonlar!$A$2:$D$776,4,0) -> 999999999 | J22: =IF(A22=A21, J21, J21+1) -> 9 | K22: =IF(I22=1000000,"","Sabit") -> Sabit
A23: OP_A020330_A | B23: OP_A020330_A_1 | C23: Oprt53 | D23: Oprt52 | E23: Oprt92 | H23: 9.2 | I23: =VLOOKUP(A23,İstasyonlar!$A$2:$D$776,4,0) -> 999999999 | J23: =IF(A23=A22, J22, J22+1) -> 10 | K23: =IF(I23=1000000,"","Sabit") -> Sabit
A24: OP_A020330_A | B24: OP_A020330_A_2 | C24: Oprt53 | D24: Oprt52 | E24: Oprt92 | H24: 9.2 | I24: =VLOOKUP(A24,İstasyonlar!$A$2:$D$776,4,0) -> 999999999 | J24: =IF(A24=A23, J23, J23+1) -> 10 | K24: =IF(I24=1000000,"","Sabit") -> Sabit
A25: OP_A020350 | B25: OP_A020350_7 | C25: Oprt61 | H25: 5.5 | I25: =VLOOKUP(A25,İstasyonlar!$A$2:$D$776,4,0) -> 999999999 | J25: =IF(A25=A24, J24, J24+1) -> 11 | K25: =IF(I25=1000000,"","Sabit") -> Sabit
A26: OP_A020350 | B26: OP_A020350_10 | C26: Oprt61 | H26: 3.8 | I26: =VLOOKUP(A26,İstasyonlar!$A$2:$D$776,4,0) -> 999999999 | J26: =IF(A26=A25, J25, J25+1) -> 11 | K26: =IF(I26=1000000,"","Sabit") -> Sabit
A27: OP_A020350 | B27: OP_A020350_4 | C27: Oprt61 | H27: 2.5 | I27: =VLOOKUP(A27,İstasyonlar!$A$2:$D$776,4,0) -> 999999999 | J27: =IF(A27=A26, J26, J26+1) -> 11 | K27: =IF(I27=1000000,"","Sabit") -> Sabit
A28: OP_A020350 | B28: OP_A020350_5 | C28: Oprt61 | H28: 2.7 | I28: =VLOOKUP(A28,İstasyonlar!$A$2:$D$776,4,0) -> 999999999 | J28: =IF(A28=A27, J27, J27+1) -> 11 | K28: =IF(I28=1000000,"","Sabit") -> Sabit
A29: OP_A020390 | B29: OP_A020390_1 | C29: Oprt60 | D29: Oprt21 | H29: 3.9 | I29: =VLOOKUP(A29,İstasyonlar!$A$2:$D$776,4,0) -> 1000000 | J29: =IF(A29=A28, J28, J28+1) -> 12 | K29: =IF(I29=1000000,"","Sabit")
A30: OP_A020390 | B30: OP_A020390_2 | C30: Oprt60 | D30: Oprt21 | H30: 5.5 | I30: =VLOOKUP(A30,İstasyonlar!$A$2:$D$776,4,0) -> 1000000 | J30: =IF(A30=A29, J29, J29+1) -> 12 | K30: =IF(I30=1000000,"","Sabit")
A31: OP_A020390 | B31: OP_A020390_3 | C31: Oprt60 | D31: Oprt21 | H31: 7.2 | I31: =VLOOKUP(A31,İstasyonlar!$A$2:$D$776,4,0) -> 1000000 | J31: =IF(A31=A30, J30, J30+1) -> 12 | K31: =IF(I31=1000000,"","Sabit")
A32: OP_A020420 | B32: OP_A020420_1 | C32: Oprt27 | H32: 11.5 | I32: =VLOOKUP(A32,İstasyonlar!$A$2:$D$776,4,0) -> 1000000 | J32: =IF(A32=A31, J31, J31+1) -> 13 | K32: =IF(I32=1000000,"","Sabit")
A33: OP_A020450 | B33: OP_A020450_1 | C33: Oprt45 | D33: Oprt27 | H33: 6.2 | I33: =VLOOKUP(A33,İstasyonlar!$A$2:$D$776,4,0) -> 1000000 | J33: =IF(A33=A32, J32, J32+1) -> 14 | K33: =IF(I33=1000000,"","Sabit")
A34: OP_A020450 | B34: OP_A020450_2 | C34: Oprt45 | D34: Oprt27 | H34: 3.1 | I34: =VLOOKUP(A34,İstasyonlar!$A$2:$D$776,4,0) -> 1000000 | J34: =IF(A34=A33, J33, J33+1) -> 14 | K34: =IF(I34=1000000,"","Sabit")
A35: OP_A020480 | B35: OP_A020480_1 | C35: Oprt75 | H35: 3.2 | I35: =VLOOKUP(A35,İstasyonlar!$A$2:$D$776,4,0) -> 999999999 | J35: =IF(A35=A34, J34, J34+1) -> 15 | K35: =IF(I35=1000000,"","Sabit") -> Sabit
A36: OP_A020480 | B36: OP_A020480_2 | C36: Oprt75 | H36: 5.5 | I36: =VLOOKUP(A36,İstasyonlar!$A$2:$D$776,4,0) -> 999999999 | J36: =IF(A36=A35, J35, J35+1) -> 15 | K36: =IF(I36=1000000,"","Sabit") -> Sabit
A37: OP_A020480 | B37: OP_A020480_3 | C37: Oprt75 | H37: 5 | I37: =VLOOKUP(A37,İstasyonlar!$A$2:$D$776,4,0) -> 999999999 | J37: =IF(A37=A36, J36, J36+1) -> 15 | K37: =IF(I37=1000000,"","Sabit") -> Sabit
A38: OP_A020500 | B38: OP_A020500_1 | C38: Oprt28 | H38: 6 | I38: =VLOOKUP(A38,İstasyonlar!$A$2:$D$776,4,0) -> 999999999 | J38: =IF(A38=A37, J37, J37+1) -> 16 | K38: =IF(I38=1000000,"","Sabit") -> Sabit
A39: OP_A020500 | B39: OP_A020500_3 | C39: Oprt28 | H39: 8.1 | I39: =VLOOKUP(A39,İstasyonlar!$A$2:$D$776,4,0) -> 999999999 | J39: =IF(A39=A38, J38, J38+1) -> 16 | K39: =IF(I39=1000000,"","Sabit") -> Sabit
A40: OP_A020500 | B40: OP_A020500_4 | C40: Oprt28 | H40: 3.8 | I40: =VLOOKUP(A40,İstasyonlar!$A$2:$D$776,4,0) -> 999999999 | J40: =IF(A40=A39, J39, J39+1) -> 16 | K40: =IF(I40=1000000,"","Sabit") -> Sabit
...

Sheet 77514 için istasyonlar
A1: İstasyon adres | B1: Operasyon No | C1: İstasyon Bilgisi Operatör 1 | D1: İstasyon Bilgisi Operatör 2 | E1: İstasyon Bilgisi Operatör 3 | F1: İstasyon Bilgisi Operatör 4 | G1: İstasyon Bilgisi Operatör 5 | H1: SÜRE (SN) | I1: Ceza | J1: Sıra
A2: OP_A020060 | B2: OP_A020060_1 | C2: Oprt15 | D2: Oprt11 | E2: Oprt3 | H2: 6.1 | I2: =VLOOKUP(A2,İstasyonlar!$A$2:$D$776,4,0) -> 1000000 | J2: 1 | K2: =IF(I2=1000000,"","Sabit")
A3: OP_A020060 | B3: OP_A020060_2 | C3: Oprt15 | D3: Oprt11 | E3: Oprt3 | H3: 6.1 | I3: =VLOOKUP(A3,İstasyonlar!$A$2:$D$776,4,0) -> 1000000 | J3: =IF(A3=A2, J2, J2+1) -> 1 | K3: =IF(I3=1000000,"","Sabit")
A4: OP_A020080 | B4: OP_A020080_1 | C4: Oprt3 | D4: Oprt4 | E4: Oprt15 | H4: 5.8 | I4: =VLOOKUP(A4,İstasyonlar!$A$2:$D$776,4,0) -> 999999999 | J4: =IF(A4=A3, J3, J3+1) -> 2 | K4: =IF(I4=1000000,"","Sabit") -> Sabit
A5: OP_A020080 | B5: OP_A020080_2 | C5: Oprt3 | D5: Oprt4 | E5: Oprt15 | H5: 6.4 | I5: =VLOOKUP(A5,İstasyonlar!$A$2:$D$776,4,0) -> 999999999 | J5: =IF(A5=A4, J4, J4+1) -> 2 | K5: =IF(I5=1000000,"","Sabit") -> Sabit
A6: OP_A020080_A | B6: OP_A020080_A_2 | C6: Oprt4 | D6: Oprt3 | H6: 6.4 | I6: =VLOOKUP(A6,İstasyonlar!$A$2:$D$776,4,0) -> 999999999 | J6: =IF(A6=A5, J5, J5+1) -> 3 | K6: =IF(I6=1000000,"","Sabit") -> Sabit
A7: OP_A020080_A | B7: OP_A020080_A_3 | C7: Oprt4 | D7: Oprt3 | H7: 1 | I7: =VLOOKUP(A7,İstasyonlar!$A$2:$D$776,4,0) -> 999999999 | J7: =IF(A7=A6, J6, J6+1) -> 3 | K7: =IF(I7=1000000,"","Sabit") -> Sabit
A8: OP_A020140 | B8: OP_A020140_1 | C8: Oprt93 | D8: Oprt16 | H8: 9.5 | I8: =VLOOKUP(A8,İstasyonlar!$A$2:$D$776,4,0) -> 1000000 | J8: =IF(A8=A7, J7, J7+1) -> 4 | K8: =IF(I8=1000000,"","Sabit")
A9: OP_A020140 | B9: OP_A020140_2 | C9: Oprt93 | D9: Oprt16 | H9: 3.1 | I9: =VLOOKUP(A9,İstasyonlar!$A$2:$D$776,4,0) -> 1000000 | J9: =IF(A9=A8, J8, J8+1) -> 4 | K9: =IF(I9=1000000,"","Sabit")
A10: OP_A020160 | B10: OP_A020160_1 | C10: Oprt67 | D10: Oprt22 | E10: Oprt11 | H10: 6.5 | I10: =VLOOKUP(A10,İstasyonlar!$A$2:$D$776,4,0) -> 1000000 | J10: =IF(A10=A9, J9, J9+1) -> 5 | K10: =IF(I10=1000000,"","Sabit")
A11: OP_A020160 | B11: OP_A020160_2 | C11: Oprt67 | D11: Oprt22 | E11: Oprt11 | H11: 3.1 | I11: =VLOOKUP(A11,İstasyonlar!$A$2:$D$776,4,0) -> 1000000 | J11: =IF(A11=A10, J10, J10+1) -> 5 | K11: =IF(I11=1000000,"","Sabit")
A12: OP_A020160 | B12: OP_A020160_3 | C12: Oprt67 | D12: Oprt22 | E12: Oprt11 | H12: 0.3 | I12: =VLOOKUP(A12,İstasyonlar!$A$2:$D$776,4,0) -> 1000000 | J12: =IF(A12=A11, J11, J11+1) -> 5 | K12: =IF(I12=1000000,"","Sabit")
A13: OP_A020220 | B13: OP_A020220_1 | C13: Oprt11 | E13: Oprt69 | F13: Oprt3 | H13: 6.5 | I13: =VLOOKUP(A13,İstasyonlar!$A$2:$D$776,4,0) -> 1000000 | J13: =IF(A13=A12, J12, J12+1) -> 6 | K13: =IF(I13=1000000,"","Sabit")
A14: OP_A020220 | B14: OP_A020220_2 | C14: Oprt11 | E14: Oprt69 | F14: Oprt3 | H14: 2.8 | I14: =VLOOKUP(A14,İstasyonlar!$A$2:$D$776,4,0) -> 1000000 | J14: =IF(A14=A13, J13, J13+1) -> 6 | K14: =IF(I14=1000000,"","Sabit")
A15: OP_A020220 | B15: OP_A020220_3 | C15: Oprt11 | E15: Oprt69 | F15: Oprt3 | H15: 3.1 | I15: =VLOOKUP(A15,İstasyonlar!$A$2:$D$776,4,0) -> 1000000 | J15: =IF(A15=A14, J14, J14+1) -> 6 | K15: =IF(I15=1000000,"","Sabit")
A16: OP_A020190_A | B16: OP_A020190_A_3 | C16: Oprt80 | D16: Oprt87 | H16: 4.3 | I16: =VLOOKUP(A16,İstasyonlar!$A$2:$D$776,4,0) -> 1000000 | J16: =IF(A16=A15, J15, J15+1) -> 7 | K16: =IF(I16=1000000,"","Sabit")
A17: OP_A020300 | B17: OP_A020300_1 | C17: Oprt92 | D17: Oprt93 | H17: 5.3 | I17: =VLOOKUP(A17,İstasyonlar!$A$2:$D$776,4,0) -> 999999999 | J17: =IF(A17=A16, J16, J16+1) -> 8 | K17: =IF(I17=1000000,"","Sabit") -> Sabit
A18: OP_A020300 | B18: OP_A020300_2 | C18: Oprt92 | D18: Oprt93 | H18: 6.4 | I18: =VLOOKUP(A18,İstasyonlar!$A$2:$D$776,4,0) -> 999999999 | J18: =IF(A18=A17, J17, J17+1) -> 8 | K18: =IF(I18=1000000,"","Sabit") -> Sabit
A19: OP_A020300 | B19: OP_A020300_3 | C19: Oprt92 | D19: Oprt93 | H19: 2.4 | I19: =VLOOKUP(A19,İstasyonlar!$A$2:$D$776,4,0) -> 999999999 | J19: =IF(A19=A18, J18, J18+1) -> 8 | K19: =IF(I19=1000000,"","Sabit") -> Sabit
A20: OP_A020300 | B20: OP_A020300_4 | C20: Oprt92 | D20: Oprt93 | H20: 2.7 | I20: =VLOOKUP(A20,İstasyonlar!$A$2:$D$776,4,0) -> 999999999 | J20: =IF(A20=A19, J19, J19+1) -> 8 | K20: =IF(I20=1000000,"","Sabit") -> Sabit
A21: OP_A020330 | B21: OP_A020330_1 | C21: Oprt52 | D21: Oprt53 | G21: Oprt3 | H21: 9.2 | I21: =VLOOKUP(A21,İstasyonlar!$A$2:$D$776,4,0) -> 999999999 | J21: =IF(A21=A20, J20, J20+1) -> 9 | K21: =IF(I21=1000000,"","Sabit") -> Sabit
A22: OP_A020330 | B22: OP_A020330_2 | C22: Oprt52 | D22: Oprt53 | G22: Oprt3 | H22: 9.2 | I22: =VLOOKUP(A22,İstasyonlar!$A$2:$D$776,4,0) -> 999999999 | J22: =IF(A22=A21, J21, J21+1) -> 9 | K22: =IF(I22=1000000,"","Sabit") -> Sabit
A23: OP_A020330_A | B23: OP_A020330_A_1 | C23: Oprt53 | D23: Oprt52 | E23: Oprt92 | H23: 9.2 | I23: =VLOOKUP(A23,İstasyonlar!$A$2:$D$776,4,0) -> 999999999 | J23: =IF(A23=A22, J22, J22+1) -> 10 | K23: =IF(I23=1000000,"","Sabit") -> Sabit
A24: OP_A020330_A | B24: OP_A020330_A_2 | C24: Oprt53 | D24: Oprt52 | E24: Oprt92 | H24: 9.2 | I24: =VLOOKUP(A24,İstasyonlar!$A$2:$D$776,4,0) -> 999999999 | J24: =IF(A24=A23, J23, J23+1) -> 10 | K24: =IF(I24=1000000,"","Sabit") -> Sabit
A25: OP_A020350 | B25: OP_A020350_7 | C25: Oprt61 | H25: 5.5 | I25: =VLOOKUP(A25,İstasyonlar!$A$2:$D$776,4,0) -> 999999999 | J25: =IF(A25=A24, J24, J24+1) -> 11 | K25: =IF(I25=1000000,"","Sabit") -> Sabit
A26: OP_A020350 | B26: OP_A020350_8 | C26: Oprt61 | H26: 3.1 | I26: =VLOOKUP(A26,İstasyonlar!$A$2:$D$776,4,0) -> 999999999 | J26: =IF(A26=A25, J25, J25+1) -> 11 | K26: =IF(I26=1000000,"","Sabit") -> Sabit
A27: OP_A020350 | B27: OP_A020350_9 | C27: Oprt61 | H27: 4.5 | I27: =VLOOKUP(A27,İstasyonlar!$A$2:$D$776,4,0) -> 999999999 | J27: =IF(A27=A26, J26, J26+1) -> 11 | K27: =IF(I27=1000000,"","Sabit") -> Sabit
A28: OP_A020350 | B28: OP_A020350_5 | C28: Oprt61 | H28: 2.7 | I28: =VLOOKUP(A28,İstasyonlar!$A$2:$D$776,4,0) -> 999999999 | J28: =IF(A28=A27, J27, J27+1) -> 11 | K28: =IF(I28=1000000,"","Sabit") -> Sabit
A29: OP_A020390 | B29: OP_A020390_1 | C29: Oprt60 | D29: Oprt21 | H29: 3.9 | I29: =VLOOKUP(A29,İstasyonlar!$A$2:$D$776,4,0) -> 1000000 | J29: =IF(A29=A28, J28, J28+1) -> 12 | K29: =IF(I29=1000000,"","Sabit")
A30: OP_A020390 | B30: OP_A020390_2 | C30: Oprt60 | D30: Oprt21 | H30: 5.5 | I30: =VLOOKUP(A30,İstasyonlar!$A$2:$D$776,4,0) -> 1000000 | J30: =IF(A30=A29, J29, J29+1) -> 12 | K30: =IF(I30=1000000,"","Sabit")
A31: OP_A020390 | B31: OP_A020390_3 | C31: Oprt60 | D31: Oprt21 | H31: 7.2 | I31: =VLOOKUP(A31,İstasyonlar!$A$2:$D$776,4,0) -> 1000000 | J31: =IF(A31=A30, J30, J30+1) -> 12 | K31: =IF(I31=1000000,"","Sabit")
A32: OP_A020420 | B32: OP_A020420_1 | C32: Oprt27 | H32: 11.5 | I32: =VLOOKUP(A32,İstasyonlar!$A$2:$D$776,4,0) -> 1000000 | J32: =IF(A32=A31, J31, J31+1) -> 13 | K32: =IF(I32=1000000,"","Sabit")
A33: OP_A020450 | B33: OP_A020450_1 | C33: Oprt45 | D33: Oprt27 | H33: 6.2 | I33: =VLOOKUP(A33,İstasyonlar!$A$2:$D$776,4,0) -> 1000000 | J33: =IF(A33=A32, J32, J32+1) -> 14 | K33: =IF(I33=1000000,"","Sabit")
A34: OP_A020450 | B34: OP_A020450_2 | C34: Oprt45 | D34: Oprt27 | H34: 3.1 | I34: =VLOOKUP(A34,İstasyonlar!$A$2:$D$776,4,0) -> 1000000 | J34: =IF(A34=A33, J33, J33+1) -> 14 | K34: =IF(I34=1000000,"","Sabit")
A35: OP_A020480 | B35: OP_A020480_1 | C35: Oprt75 | H35: 3.2 | I35: =VLOOKUP(A35,İstasyonlar!$A$2:$D$776,4,0) -> 999999999 | J35: =IF(A35=A34, J34, J34+1) -> 15 | K35: =IF(I35=1000000,"","Sabit") -> Sabit
A36: OP_A020480 | B36: OP_A020480_2 | C36: Oprt75 | H36: 5.5 | I36: =VLOOKUP(A36,İstasyonlar!$A$2:$D$776,4,0) -> 999999999 | J36: =IF(A36=A35, J35, J35+1) -> 15 | K36: =IF(I36=1000000,"","Sabit") -> Sabit
A37: OP_A020480 | B37: OP_A020480_3 | C37: Oprt75 | H37: 5 | I37: =VLOOKUP(A37,İstasyonlar!$A$2:$D$776,4,0) -> 999999999 | J37: =IF(A37=A36, J36, J36+1) -> 15 | K37: =IF(I37=1000000,"","Sabit") -> Sabit
A38: OP_A020500 | B38: OP_A020500_1 | C38: Oprt28 | H38: 6 | I38: =VLOOKUP(A38,İstasyonlar!$A$2:$D$776,4,0) -> 999999999 | J38: =IF(A38=A37, J37, J37+1) -> 16 | K38: =IF(I38=1000000,"","Sabit") -> Sabit
A39: OP_A020500 | B39: OP_A020500_3 | C39: Oprt28 | H39: 8.1 | I39: =VLOOKUP(A39,İstasyonlar!$A$2:$D$776,4,0) -> 999999999 | J39: =IF(A39=A38, J38, J38+1) -> 16 | K39: =IF(I39=1000000,"","Sabit") -> Sabit
A40: OP_A020500 | B40: OP_A020500_4 | C40: Oprt28 | H40: 3.8 | I40: =VLOOKUP(A40,İstasyonlar!$A$2:$D$776,4,0) -> 999999999 | J40: =IF(A40=A39, J39, J39+1) -> 16 | K40: =IF(I40=1000000,"","Sabit") -> Sabit
...

Sheet 78472 için istasyonlar
A1: İstasyon adres | B1: Operasyon No | C1: İstasyon Bilgisi Operatör 1 | D1: İstasyon Bilgisi Operatör 2 | E1: İstasyon Bilgisi Operatör 3 | F1: İstasyon Bilgisi Operatör 4 | G1: İstasyon Bilgisi Operatör 5 | H1: SÜRE (SN) | I1: Ceza | J1: Sıra
A2: OP_A020060 | B2: OP_A020060_1 | C2: Oprt15 | D2: Oprt11 | E2: Oprt3 | H2: 6.1 | I2: =VLOOKUP(A2,İstasyonlar!$A$2:$D$776,4,0) -> 1000000 | J2: 1 | K2: =IF(I2=1000000,"","Sabit")
A3: OP_A020060 | B3: OP_A020060_2 | C3: Oprt15 | D3: Oprt11 | E3: Oprt3 | H3: 6.1 | I3: =VLOOKUP(A3,İstasyonlar!$A$2:$D$776,4,0) -> 1000000 | J3: =IF(A3=A2, J2, J2+1) -> 1 | K3: =IF(I3=1000000,"","Sabit")
A4: OP_A020080 | B4: OP_A020080_1 | C4: Oprt3 | D4: Oprt4 | E4: Oprt15 | H4: 5.8 | I4: =VLOOKUP(A4,İstasyonlar!$A$2:$D$776,4,0) -> 999999999 | J4: =IF(A4=A3, J3, J3+1) -> 2 | K4: =IF(I4=1000000,"","Sabit") -> Sabit
A5: OP_A020080 | B5: OP_A020080_2 | C5: Oprt3 | D5: Oprt4 | E5: Oprt15 | H5: 6.4 | I5: =VLOOKUP(A5,İstasyonlar!$A$2:$D$776,4,0) -> 999999999 | J5: =IF(A5=A4, J4, J4+1) -> 2 | K5: =IF(I5=1000000,"","Sabit") -> Sabit
A6: OP_A020080_A | B6: OP_A020080_A_2 | C6: Oprt4 | D6: Oprt3 | H6: 6.4 | I6: =VLOOKUP(A6,İstasyonlar!$A$2:$D$776,4,0) -> 999999999 | J6: =IF(A6=A5, J5, J5+1) -> 3 | K6: =IF(I6=1000000,"","Sabit") -> Sabit
A7: OP_A020080_A | B7: OP_A020080_A_3 | C7: Oprt4 | D7: Oprt3 | H7: 1 | I7: =VLOOKUP(A7,İstasyonlar!$A$2:$D$776,4,0) -> 999999999 | J7: =IF(A7=A6, J6, J6+1) -> 3 | K7: =IF(I7=1000000,"","Sabit") -> Sabit
A8: OP_A020140 | B8: OP_A020140_1 | C8: Oprt93 | D8: Oprt16 | H8: 9.5 | I8: =VLOOKUP(A8,İstasyonlar!$A$2:$D$776,4,0) -> 1000000 | J8: =IF(A8=A7, J7, J7+1) -> 4 | K8: =IF(I8=1000000,"","Sabit")
A9: OP_A020140 | B9: OP_A020140_2 | C9: Oprt93 | D9: Oprt16 | H9: 3.1 | I9: =VLOOKUP(A9,İstasyonlar!$A$2:$D$776,4,0) -> 1000000 | J9: =IF(A9=A8, J8, J8+1) -> 4 | K9: =IF(I9=1000000,"","Sabit")
A10: OP_A020160 | B10: OP_A020160_1 | C10: Oprt67 | D10: Oprt22 | E10: Oprt11 | H10: 6.5 | I10: =VLOOKUP(A10,İstasyonlar!$A$2:$D$776,4,0) -> 1000000 | J10: =IF(A10=A9, J9, J9+1) -> 5 | K10: =IF(I10=1000000,"","Sabit")
A11: OP_A020160 | B11: OP_A020160_2 | C11: Oprt67 | D11: Oprt22 | E11: Oprt11 | H11: 3.1 | I11: =VLOOKUP(A11,İstasyonlar!$A$2:$D$776,4,0) -> 1000000 | J11: =IF(A11=A10, J10, J10+1) -> 5 | K11: =IF(I11=1000000,"","Sabit")
A12: OP_A020160 | B12: OP_A020160_3 | C12: Oprt67 | D12: Oprt22 | E12: Oprt11 | H12: 0.3 | I12: =VLOOKUP(A12,İstasyonlar!$A$2:$D$776,4,0) -> 1000000 | J12: =IF(A12=A11, J11, J11+1) -> 5 | K12: =IF(I12=1000000,"","Sabit")
A13: OP_A020220 | B13: OP_A020220_1 | C13: Oprt11 | E13: Oprt69 | F13: Oprt3 | H13: 6.5 | I13: =VLOOKUP(A13,İstasyonlar!$A$2:$D$776,4,0) -> 1000000 | J13: =IF(A13=A12, J12, J12+1) -> 6 | K13: =IF(I13=1000000,"","Sabit")
A14: OP_A020220 | B14: OP_A020220_2 | C14: Oprt11 | E14: Oprt69 | F14: Oprt3 | H14: 2.8 | I14: =VLOOKUP(A14,İstasyonlar!$A$2:$D$776,4,0) -> 1000000 | J14: =IF(A14=A13, J13, J13+1) -> 6 | K14: =IF(I14=1000000,"","Sabit")
A15: OP_A020220 | B15: OP_A020220_3 | C15: Oprt11 | E15: Oprt69 | F15: Oprt3 | H15: 3.1 | I15: =VLOOKUP(A15,İstasyonlar!$A$2:$D$776,4,0) -> 1000000 | J15: =IF(A15=A14, J14, J14+1) -> 6 | K15: =IF(I15=1000000,"","Sabit")
A16: OP_A020190_A | B16: OP_A020190_A_3 | C16: Oprt80 | D16: Oprt87 | H16: 4.3 | I16: =VLOOKUP(A16,İstasyonlar!$A$2:$D$776,4,0) -> 1000000 | J16: =IF(A16=A15, J15, J15+1) -> 7 | K16: =IF(I16=1000000,"","Sabit")
A17: OP_A020300 | B17: OP_A020300_1 | C17: Oprt92 | D17: Oprt93 | H17: 5.3 | I17: =VLOOKUP(A17,İstasyonlar!$A$2:$D$776,4,0) -> 999999999 | J17: =IF(A17=A16, J16, J16+1) -> 8 | K17: =IF(I17=1000000,"","Sabit") -> Sabit
A18: OP_A020300 | B18: OP_A020300_2 | C18: Oprt92 | D18: Oprt93 | H18: 6.4 | I18: =VLOOKUP(A18,İstasyonlar!$A$2:$D$776,4,0) -> 999999999 | J18: =IF(A18=A17, J17, J17+1) -> 8 | K18: =IF(I18=1000000,"","Sabit") -> Sabit
A19: OP_A020300 | B19: OP_A020300_3 | C19: Oprt92 | D19: Oprt93 | H19: 2.4 | I19: =VLOOKUP(A19,İstasyonlar!$A$2:$D$776,4,0) -> 999999999 | J19: =IF(A19=A18, J18, J18+1) -> 8 | K19: =IF(I19=1000000,"","Sabit") -> Sabit
A20: OP_A020300 | B20: OP_A020300_4 | C20: Oprt92 | D20: Oprt93 | H20: 2.7 | I20: =VLOOKUP(A20,İstasyonlar!$A$2:$D$776,4,0) -> 999999999 | J20: =IF(A20=A19, J19, J19+1) -> 8 | K20: =IF(I20=1000000,"","Sabit") -> Sabit
A21: OP_A020330 | B21: OP_A020330_1 | C21: Oprt52 | D21: Oprt53 | G21: Oprt3 | H21: 9.2 | I21: =VLOOKUP(A21,İstasyonlar!$A$2:$D$776,4,0) -> 999999999 | J21: =IF(A21=A20, J20, J20+1) -> 9 | K21: =IF(I21=1000000,"","Sabit") -> Sabit
A22: OP_A020330 | B22: OP_A020330_2 | C22: Oprt52 | D22: Oprt53 | G22: Oprt3 | H22: 9.2 | I22: =VLOOKUP(A22,İstasyonlar!$A$2:$D$776,4,0) -> 999999999 | J22: =IF(A22=A21, J21, J21+1) -> 9 | K22: =IF(I22=1000000,"","Sabit") -> Sabit
A23: OP_A020330_A | B23: OP_A020330_A_1 | C23: Oprt53 | D23: Oprt52 | E23: Oprt92 | H23: 9.2 | I23: =VLOOKUP(A23,İstasyonlar!$A$2:$D$776,4,0) -> 999999999 | J23: =IF(A23=A22, J22, J22+1) -> 10 | K23: =IF(I23=1000000,"","Sabit") -> Sabit
A24: OP_A020330_A | B24: OP_A020330_A_2 | C24: Oprt53 | D24: Oprt52 | E24: Oprt92 | H24: 9.2 | I24: =VLOOKUP(A24,İstasyonlar!$A$2:$D$776,4,0) -> 999999999 | J24: =IF(A24=A23, J23, J23+1) -> 10 | K24: =IF(I24=1000000,"","Sabit") -> Sabit
A25: OP_A020350 | B25: OP_A020350_7 | C25: Oprt61 | H25: 5.5 | I25: =VLOOKUP(A25,İstasyonlar!$A$2:$D$776,4,0) -> 999999999 | J25: =IF(A25=A24, J24, J24+1) -> 11 | K25: =IF(I25=1000000,"","Sabit") -> Sabit
A26: OP_A020350 | B26: OP_A020350_8 | C26: Oprt61 | H26: 3.1 | I26: =VLOOKUP(A26,İstasyonlar!$A$2:$D$776,4,0) -> 999999999 | J26: =IF(A26=A25, J25, J25+1) -> 11 | K26: =IF(I26=1000000,"","Sabit") -> Sabit
A27: OP_A020350 | B27: OP_A020350_9 | C27: Oprt61 | H27: 4.5 | I27: =VLOOKUP(A27,İstasyonlar!$A$2:$D$776,4,0) -> 999999999 | J27: =IF(A27=A26, J26, J26+1) -> 11 | K27: =IF(I27=1000000,"","Sabit") -> Sabit
A28: OP_A020350 | B28: OP_A020350_5 | C28: Oprt61 | H28: 2.7 | I28: =VLOOKUP(A28,İstasyonlar!$A$2:$D$776,4,0) -> 999999999 | J28: =IF(A28=A27, J27, J27+1) -> 11 | K28: =IF(I28=1000000,"","Sabit") -> Sabit
A29: OP_A020390 | B29: OP_A020390_1 | C29: Oprt60 | D29: Oprt21 | H29: 3.9 | I29: =VLOOKUP(A29,İstasyonlar!$A$2:$D$776,4,0) -> 1000000 | J29: =IF(A29=A28, J28, J28+1) -> 12 | K29: =IF(I29=1000000,"","Sabit")
A30: OP_A020390 | B30: OP_A020390_2 | C30: Oprt60 | D30: Oprt21 | H30: 5.5 | I30: =VLOOKUP(A30,İstasyonlar!$A$2:$D$776,4,0) -> 1000000 | J30: =IF(A30=A29, J29, J29+1) -> 12 | K30: =IF(I30=1000000,"","Sabit")
A31: OP_A020390 | B31: OP_A020390_3 | C31: Oprt60 | D31: Oprt21 | H31: 7.2 | I31: =VLOOKUP(A31,İstasyonlar!$A$2:$D$776,4,0) -> 1000000 | J31: =IF(A31=A30, J30, J30+1) -> 12 | K31: =IF(I31=1000000,"","Sabit")
A32: OP_A020420 | B32: OP_A020420_1 | C32: Oprt27 | H32: 11.5 | I32: =VLOOKUP(A32,İstasyonlar!$A$2:$D$776,4,0) -> 1000000 | J32: =IF(A32=A31, J31, J31+1) -> 13 | K32: =IF(I32=1000000,"","Sabit")
A33: OP_A020450 | B33: OP_A020450_1 | C33: Oprt45 | D33: Oprt27 | H33: 6.2 | I33: =VLOOKUP(A33,İstasyonlar!$A$2:$D$776,4,0) -> 1000000 | J33: =IF(A33=A32, J32, J32+1) -> 14 | K33: =IF(I33=1000000,"","Sabit")
A34: OP_A020450 | B34: OP_A020450_2 | C34: Oprt45 | D34: Oprt27 | H34: 3.1 | I34: =VLOOKUP(A34,İstasyonlar!$A$2:$D$776,4,0) -> 1000000 | J34: =IF(A34=A33, J33, J33+1) -> 14 | K34: =IF(I34=1000000,"","Sabit")
A35: OP_A020480 | B35: OP_A020480_1 | C35: Oprt75 | H35: 3.2 | I35: =VLOOKUP(A35,İstasyonlar!$A$2:$D$776,4,0) -> 999999999 | J35: =IF(A35=A34, J34, J34+1) -> 15 | K35: =IF(I35=1000000,"","Sabit") -> Sabit
A36: OP_A020480 | B36: OP_A020480_2 | C36: Oprt75 | H36: 5.5 | I36: =VLOOKUP(A36,İstasyonlar!$A$2:$D$776,4,0) -> 999999999 | J36: =IF(A36=A35, J35, J35+1) -> 15 | K36: =IF(I36=1000000,"","Sabit") -> Sabit
A37: OP_A020480 | B37: OP_A020480_3 | C37: Oprt75 | H37: 5 | I37: =VLOOKUP(A37,İstasyonlar!$A$2:$D$776,4,0) -> 999999999 | J37: =IF(A37=A36, J36, J36+1) -> 15 | K37: =IF(I37=1000000,"","Sabit") -> Sabit
A38: OP_A020500 | B38: OP_A020500_1 | C38: Oprt28 | H38: 6 | I38: =VLOOKUP(A38,İstasyonlar!$A$2:$D$776,4,0) -> 999999999 | J38: =IF(A38=A37, J37, J37+1) -> 16 | K38: =IF(I38=1000000,"","Sabit") -> Sabit
A39: OP_A020500 | B39: OP_A020500_3 | C39: Oprt28 | H39: 8.1 | I39: =VLOOKUP(A39,İstasyonlar!$A$2:$D$776,4,0) -> 999999999 | J39: =IF(A39=A38, J38, J38+1) -> 16 | K39: =IF(I39=1000000,"","Sabit") -> Sabit
A40: OP_A020500 | B40: OP_A020500_4 | C40: Oprt28 | H40: 3.8 | I40: =VLOOKUP(A40,İstasyonlar!$A$2:$D$776,4,0) -> 999999999 | J40: =IF(A40=A39, J39, J39+1) -> 16 | K40: =IF(I40=1000000,"","Sabit") -> Sabit
...

Sheet Model Üretim Bilgileri
B3: Model | C3: 78446
B4: Üretim Süresi (Bant giriş-çıkış) | C4: 0.065092593
B5: Üretilen Adet | C5: 247
B6: Devamsız Personeller | C6: Oprt80
C7: Oprt83
C8: Oprt61

Sheet SABİT İST GÜNCEL.....
A1: İstasyonlar | B1: Sabit İstasyonlar
A2: OP_A020800_B
A3: OP_A020800_B
A4: OP_A020800_B
A5: OP_A020800_B
A6: OP_A022700 | B6: Sabit
A7: OP_A022700 | B7: Sabit
A8: OP_A022700 | B8: Sabit
A9: OP_A022700 | B9: Sabit
A10: OP_A022700 | B10: Sabit
A11: OP_A022700 | B11: Sabit
A12: OP_A022700 | B12: Sabit
A13: OP_A022700 | B13: Sabit
A14: OP_A021170
A15: OP_A021170
A16: OP_A021170
A17: OP_A021170
A18: OP_A021170
A19: OP_A021170
A20: OP_A021170
A21: OP_A021170
A22: OP_A021170
A23: OP_A021170
A24: OP_A021170
A25: OP_A020080 | B25: Sabit
A26: OP_A020080 | B26: Sabit
A27: OP_A022370 | B27: Sabit
A28: OP_A022370 | B28: Sabit
A29: OP_A022370 | B29: Sabit
A30: OP_A022370 | B30: Sabit
A31: OP_A022370 | B31: Sabit
A32: OP_A022370 | B32: Sabit
A33: OP_A022370 | B33: Sabit
A34: OP_A022370 | B34: Sabit
A35: OP_A022370 | B35: Sabit
A36: OP_A022370 | B36: Sabit
... A91: OP_AÖYB2 | B91: Sabit
A92: OP_A022490_A
A93: OP_A022490_A
A94: OP_A022490_A
...
